<?xml version="1.0" ?>
<!-- =================================================================================== -->
<!-- |    This document was autogenerated by xacro from /home/hayden/cmu/courses/16745_OCRL/ros2_ws/src/cmu_zoe2/zoe2_description/urdf/zoe2.urdf.xacro | -->
<!-- |    EDITING THIS FILE BY HAND IS NOT RECOMMENDED                                 | -->
<!-- =================================================================================== -->
<robot name="zoe2">
  <material name="black">
    <color rgba="0.0 0.0 0.0 1.0"/>
  </material>
  <material name="blue">
    <color rgba="0.0 0.0 0.8 1.0"/>
  </material>
  <material name="green">
    <color rgba="0.0 1.0 0.0 1.0"/>
  </material>
  <material name="dark_grey">
    <color rgba="0.2 0.2 0.2 1.0"/>
  </material>
  <material name="grey">
    <color rgba="0.5 0.5 0.5 1.0"/>
  </material>
  <material name="light_grey">
    <color rgba="0.8 0.8 0.8 1.0"/>
  </material>
  <material name="orange">
    <color rgba="1.0 0.4235294117647059 0.0392156862745098 1.0"/>
  </material>
  <material name="brown">
    <color rgba="0.8705882352941177 0.8117647058823529 0.7647058823529411 1.0"/>
  </material>
  <material name="red">
    <color rgba="0.8 0.0 0.0 1.0"/>
  </material>
  <material name="white">
    <color rgba="1.0 1.0 1.0 1.0"/>
  </material>
  <!-- LINKS -->
  <link name="base_link">
    </link>
  <link name="chassis">
    <inertial>
      <origin rpy="0 0 0" xyz="0 0 0"/>
      <mass value="651.498299444812"/>
      <inertia ixx="149.816150034198" ixy="2.25656686320975E-10" ixz="1.4248945896711E-08" iyy="204.954522277079" iyz="-0.376718299070616" izz="79.5488628930089"/>
    </inertial>
    <visual>
      <origin rpy="0 0 0" xyz="0 0 0"/>
      <geometry>
        <mesh filename="meshes/chassis.obj"/>
      </geometry>
      <material name="">
        <color rgba="0.866666666666667 0.909803921568627 1 1"/>
      </material>
    </visual>
    <collision>
      <origin rpy="0 0 0" xyz="0 0 0.2"/>
      <geometry>
        <!-- <mesh
                        filename="file://$(find zoe2_description)/meshes/zoe2/collision/chassis.STL" /> -->
        <box size="1.2 1.5 0.5"/>
      </geometry>
    </collision>
  </link>
  <link name="front_roll">
    <inertial>
      <origin rpy="1.5707963267948966 0 0" xyz="0 0 0"/>
      <mass value="1.60265212368031"/>
      <inertia ixx="0.00789007052519473" ixy="-4.51083375595945E-06" ixz="-3.52376942846933E-05" iyy="0.00778556714593041" iyz="1.5780343532552E-06" izz="0.00273377335912292"/>
    </inertial>
    <visual>
      <origin rpy="1.5707963267948966 0 0" xyz="0 0 0"/>
      <geometry>
        <mesh filename="meshes/back_hinge.obj"/>
      </geometry>
      <material name="">
        <color rgba="0.866666666666667 0.909803921568627 1 1"/>
      </material>
    </visual>
    <collision>
      <origin rpy="1.5707963267948966 0 0" xyz="0 0 0"/>
      <geometry>
        <!-- <mesh
                        filename="file://$(find zoe2_description)/meshes/zoe2/collision/back_hinge.STL" /> -->
        <box size="0.1 0.1 0.4"/>
      </geometry>
    </collision>
  </link>
  <link name="wheel_front_right">
    <inertial>
      <origin rpy="0 0 1.5707963267948966" xyz="0 0 0"/>
      <mass value="32.3144669983568"/>
      <inertia ixx="1.03582581735133" ixy="3.69335039891439E-06" ixz="9.72371372309766E-09" iyy="1.97706054850814" iyz="-4.49800950049796E-08" izz="1.03582581231329"/>
    </inertial>
    <visual>
      <origin rpy="0 0 1.5707963267948966" xyz="0 0 0"/>
      <geometry>
        <mesh filename="meshes/wheel_back_right.obj"/>
      </geometry>
      <material name="">
        <color rgba="0.294117647058824 0.294117647058824 0.294117647058824 1"/>
      </material>
    </visual>
    <collision>
      <origin rpy="0 -1.5707963267948966 0" xyz="0 0 0"/>
      <geometry>
        <!-- <mesh
                        filename="file://$(find zoe2_description)/meshes/zoe2/collision/wheel_back_right.STL" /> -->
        <cylinder length="0.05" radius="0.325"/>
      </geometry>
    </collision>
  </link>
  <link name="wheel_front_left">
    <inertial>
      <origin rpy="0 0 -1.5707963267948966" xyz="0 0 0"/>
      <mass value="32.3144669983568"/>
      <inertia ixx="1.03582581735133" ixy="3.69335039891439E-06" ixz="9.72371372309766E-09" iyy="1.97706054850814" iyz="-4.49800950049796E-08" izz="1.03582581231329"/>
    </inertial>
    <visual>
      <origin rpy="0 0 -1.5707963267948966" xyz="0 0 0"/>
      <geometry>
        <mesh filename="meshes/wheel_back_right.obj"/>
      </geometry>
      <material name="">
        <color rgba="0.294117647058824 0.294117647058824 0.294117647058824 1"/>
      </material>
    </visual>
    <collision>
      <origin rpy="0 -1.5707963267948966 0" xyz="0 0 0"/>
      <geometry>
        <!-- <mesh
                        filename="file://$(find zoe2_description)/meshes/zoe2/collision/wheel_back_right.STL" /> -->
        <cylinder length="0.05" radius="0.325"/>
      </geometry>
    </collision>
  </link>
  <link name="front_axle">
    <inertial>
      <origin rpy="1.5707963267948966 0 0" xyz="0 0 0"/>
      <mass value="2.76276470983555"/>
      <inertia ixx="0.0151578893043941" ixy="-6.10514243326588E-15" ixz="-8.69280987887411E-16" iyy="0.615173226679267" iyz="-9.50117240753409E-16" izz="0.620920397735107"/>
    </inertial>
    <visual>
      <origin rpy="1.5707963267948966 0 0" xyz="0 0 -0.075"/>
      <geometry>
        <mesh filename="meshes/front_axle.obj"/>
      </geometry>
      <material name="">
        <color rgba="0.529411764705882 0.549019607843137 0.549019607843137 1"/>
      </material>
    </visual>
    <collision>
      <origin rpy="1.5707963267948966 0 0" xyz="0 0 0"/>
      <geometry>
        <!-- <mesh
                        filename="file://$(find zoe2_description)/meshes/zoe2/collision/front_axle.STL" /> -->
        <box size="1.5899999999999999 0.1 0.1"/>
      </geometry>
    </collision>
  </link>
  <link name="wheel_back_right">
    <inertial>
      <origin rpy="0 0 1.5707963267948966" xyz="0 0 0"/>
      <mass value="32.3144669983568"/>
      <inertia ixx="1.03582581735133" ixy="3.69335039891439E-06" ixz="9.72371372309766E-09" iyy="1.97706054850814" iyz="-4.49800950049796E-08" izz="1.03582581231329"/>
    </inertial>
    <visual>
      <origin rpy="0 0 1.5707963267948966" xyz="0 0 0"/>
      <geometry>
        <mesh filename="meshes/wheel_back_right.obj"/>
      </geometry>
      <material name="">
        <color rgba="0.294117647058824 0.294117647058824 0.294117647058824 1"/>
      </material>
    </visual>
    <collision>
      <origin rpy="0 -1.5707963267948966 0" xyz="0 0 0"/>
      <geometry>
        <!-- <mesh
                        filename="file://$(find zoe2_description)/meshes/zoe2/collision/wheel_back_right.STL" /> -->
        <cylinder length="0.05" radius="0.325"/>
      </geometry>
    </collision>
  </link>
  <link name="wheel_back_left">
    <inertial>
      <origin rpy="0 0 -1.5707963267948966" xyz="0 0 0"/>
      <mass value="32.3144669983568"/>
      <inertia ixx="1.03582581735133" ixy="3.69335039891439E-06" ixz="9.72371372309766E-09" iyy="1.97706054850814" iyz="-4.49800950049796E-08" izz="1.03582581231329"/>
    </inertial>
    <visual>
      <origin rpy="0 0 -1.5707963267948966" xyz="0 0 0"/>
      <geometry>
        <mesh filename="meshes/wheel_back_right.obj"/>
      </geometry>
      <material name="">
        <color rgba="0.294117647058824 0.294117647058824 0.294117647058824 1"/>
      </material>
    </visual>
    <collision>
      <origin rpy="0 -1.5707963267948966 0" xyz="0 0 0"/>
      <geometry>
        <!-- <mesh
                        filename="file://$(find zoe2_description)/meshes/zoe2/collision/wheel_back_right.STL" /> -->
        <cylinder length="0.05" radius="0.325"/>
      </geometry>
    </collision>
  </link>
  <link name="back_axle">
    <inertial>
      <origin rpy="1.5707963267948966 0 0" xyz="0 0 0"/>
      <mass value="2.76276470983555"/>
      <inertia ixx="0.0151578893043941" ixy="-6.10514243326588E-15" ixz="-8.69280987887411E-16" iyy="0.615173226679267" iyz="-9.50117240753409E-16" izz="0.620920397735107"/>
    </inertial>
    <visual>
      <origin rpy="1.5707963267948966 0 0" xyz="0 0 -0.075"/>
      <geometry>
        <mesh filename="meshes/front_axle.obj"/>
      </geometry>
      <material name="">
        <color rgba="0.529411764705882 0.549019607843137 0.549019607843137 1"/>
      </material>
    </visual>
    <collision>
      <origin rpy="1.5707963267948966 0 0" xyz="0 0 0"/>
      <geometry>
        <!-- <mesh
                        filename="file://$(find zoe2_description)/meshes/zoe2/collision/front_axle.STL" /> -->
        <box size="1.5899999999999999 0.1 0.1"/>
      </geometry>
    </collision>
  </link>
  <link name="back_roll">
    <inertial>
      <origin rpy="-1.5707963267948966 0 0" xyz="0 0 0"/>
      <mass value="1.60265212368031"/>
      <inertia ixx="0.00789007052519473" ixy="-4.51083375595945E-06" ixz="-3.52376942846933E-05" iyy="0.00778556714593041" iyz="1.5780343532552E-06" izz="0.00273377335912292"/>
    </inertial>
    <visual>
      <origin rpy="-1.5707963267948966 0 0" xyz="0 0 0"/>
      <geometry>
        <mesh filename="meshes/back_hinge.obj"/>
      </geometry>
      <material name="">
        <color rgba="0.866666666666667 0.909803921568627 1 1"/>
      </material>
    </visual>
    <collision>
      <origin rpy="-1.5707963267948966 0 0" xyz="0 0 0"/>
      <geometry>
        <!-- <mesh
                        filename="file://$(find zoe2_description)/meshes/zoe2/collision/back_hinge.STL" /> -->
        <box size="0.1 0.1 0.4"/>
      </geometry>
    </collision>
  </link>
  <!-- Link gazebo params -->
  <gazebo reference="wheel_back_left">
    <material>Gazebo/Black</material>
  </gazebo>
  <gazebo reference="wheel_back_right">
    <material>Gazebo/Black</material>
  </gazebo>
  <gazebo reference="wheel_front_right">
    <material>Gazebo/Black</material>
  </gazebo>
  <gazebo reference="wheel_front_left">
    <material>Gazebo/Black</material>
  </gazebo>
  <gazebo reference="chassis">
    <material>Gazebo/Blue</material>
  </gazebo>
  <gazebo reference="front_axle">
    <material>Gazebo/Blue</material>
  </gazebo>
  <gazebo reference="back_axle">
    <material>Gazebo/Blue</material>
  </gazebo>
  <!-- END LINKS -->
  <!-- JOINTS -->
  <joint name="chassis_joint" type="fixed">
    <parent link="base_link"/>
    <child link="chassis"/>
    <origin xyz="0 0 0.4"/>
  </joint>
  <joint name="chassis_front_roll_joint" type="fixed">
    <parent link="chassis"/>
    <child link="front_roll"/>
    <origin xyz="0 0.7549999999999999 0"/>
  </joint>
  <joint name="axle_yaw_front_joint" type="revolute">
    <parent link="front_roll"/>
    <child link="front_axle"/>
    <origin xyz="0 0.2 0"/>
    <axis xyz="0 0 1"/>
    <limit effort="10" lower="-0.7853981633974483" upper="0.7853981633974483" velocity="10"/>
  </joint>
  <joint name="wheel_front_right_joint" type="continuous">
    <parent link="front_axle"/>
    <child link="wheel_front_right"/>
    <origin xyz="0.82 0 -0.119"/>
    <axis xyz="-1 0 0"/>
  </joint>
  <joint name="wheel_front_left_joint" type="continuous">
    <parent link="front_axle"/>
    <child link="wheel_front_left"/>
    <origin xyz="-0.82 0 -0.119"/>
    <axis xyz="-1 0 0"/>
  </joint>
  <!-- temp set to fixed -->
  <joint name="axle_yaw_back_joint" type="revolute">
    <parent link="back_roll"/>
    <child link="back_axle"/>
    <origin xyz="0 -0.2 0"/>
    <limit effort="10" lower="-0.7853981633974483" upper="0.7853981633974483" velocity="10"/>
    <axis xyz="0 0 1"/>
  </joint>
  <joint name="wheel_back_right_joint" type="continuous">
    <parent link="back_axle"/>
    <child link="wheel_back_right"/>
    <origin xyz="0.82 0 -0.119"/>
    <axis xyz="-1 0 0"/>
  </joint>
  <joint name="wheel_back_left_joint" type="continuous">
    <parent link="back_axle"/>
    <child link="wheel_back_left"/>
    <origin xyz="-0.82 0 -0.119"/>
    <axis xyz="-1 0 0"/>
  </joint>
  <!-- current roll joint limits set arbitrarily... -->
  <joint name="axle_roll_back_joint" type="revolute">
    <parent link="chassis"/>
    <child link="back_roll"/>
    <origin xyz="0 -0.7549999999999999 0"/>
    <limit effort="10" lower="-0.5" upper="0.5" velocity="10"/>
    <axis xyz="0 1 0"/>
  </joint>
  <!-- END JOINTS -->
  <ros2_control name="zoe2" type="system">
    <hardware>
      <plugin>zoe2_hardware/Zoe2Hardware</plugin>
    </hardware>
    <!-- Pivot Joints -->
    <joint name="axle_yaw_front_joint">
      <state_interface name="position"/>
    </joint>
    <joint name="axle_yaw_back_joint">
      <state_interface name="position"/>
    </joint>
    <joint name="axle_roll_back_joint">
      <state_interface name="position"/>
    </joint>
    <!-- Wheel Joints -->
    <joint name="wheel_front_left_joint">
      <state_interface name="position"/>
      <state_interface name="velocity"/>
      <command_interface name="velocity">
        <param name="min">-10.0</param>
        <param name="max">10.0</param>
      </command_interface>
    </joint>
    <joint name="wheel_front_right_joint">
      <state_interface name="position"/>
      <state_interface name="velocity"/>
      <command_interface name="velocity">
        <param name="min">-10.0</param>
        <param name="max">10.0</param>
      </command_interface>
    </joint>
    <joint name="wheel_back_right_joint">
      <state_interface name="position"/>
      <state_interface name="velocity"/>
      <command_interface name="velocity">
        <param name="min">-10.0</param>
        <param name="max">10.0</param>
      </command_interface>
    </joint>
    <joint name="wheel_back_left_joint">
      <state_interface name="position"/>
      <state_interface name="velocity"/>
      <command_interface name="velocity">
        <param name="min">-10.0</param>
        <param name="max">10.0</param>
      </command_interface>
    </joint>
  </ros2_control>
</robot>
